OrderBookSim/OrderBookSim/Outputs/Log1361569052.txt
0--INFO	Added rule
0--INFO	Added rule
0--INFO	Added rule
0--INFO	Added rule
45--INFO	Enqueued order: Price: 2147483647.00, Volume: 941, Type: BUY, Market Order: 1, Participant: 9, Stock:[ID: 0, Symbol: GOOG], Time: 45, OrderNumber: 0
47--INFO	Enqueued order: Price: 100.06, Volume: 438, Type: SELL, Market Order: 0, Participant: 8, Stock:[ID: 0, Symbol: GOOG], Time: 47, OrderNumber: 1
48--INFO	Last Price Set:100.06
48--INFO	Notified Traders of trade48---Trade ID: 0, Price: 100.06, Volume: 438 between ID:[9] and ID:[8]
50--INFO	Enqueued order: Price: 2147483647.00, Volume: 707, Type: BUY, Market Order: 1, Participant: 5, Stock:[ID: 0, Symbol: GOOG], Time: 50, OrderNumber: 2
51--INFO	Enqueued order: Price: 2147483647.00, Volume: 443, Type: BUY, Market Order: 1, Participant: 3, Stock:[ID: 0, Symbol: GOOG], Time: 51, OrderNumber: 3
65--INFO	Enqueued order: Price: 100.11, Volume: 976, Type: SELL, Market Order: 0, Participant: 2, Stock:[ID: 0, Symbol: GOOG], Time: 65, OrderNumber: 4
66--INFO	Last Price Set:100.11
66--INFO	Notified Traders of trade66---Trade ID: 1, Price: 100.11, Volume: 503 between ID:[9] and ID:[2]
66--INFO	Last Price Set:100.11
66--INFO	Notified Traders of trade66---Trade ID: 2, Price: 100.11, Volume: 473 between ID:[5] and ID:[2]
70--INFO	Enqueued order: Price: 2147483647.00, Volume: 902, Type: BUY, Market Order: 1, Participant: 1, Stock:[ID: 0, Symbol: GOOG], Time: 70, OrderNumber: 5
75--INFO	Enqueued order: Price: 2147483647.00, Volume: 664, Type: BUY, Market Order: 1, Participant: 15, Stock:[ID: 0, Symbol: GOOG], Time: 75, OrderNumber: 6
80--INFO	Enqueued order: Price: 0.00, Volume: 737, Type: SELL, Market Order: 1, Participant: 6, Stock:[ID: 0, Symbol: GOOG], Time: 80, OrderNumber: 7
81--INFO	Last Price Set:100.11
81--INFO	Notified Traders of trade81---Trade ID: 3, Price: 100.11, Volume: 234 between ID:[5] and ID:[6]
81--INFO	Last Price Set:100.11
81--INFO	Notified Traders of trade81---Trade ID: 4, Price: 100.11, Volume: 443 between ID:[3] and ID:[6]
81--INFO	Last Price Set:100.11
81--INFO	Notified Traders of trade81---Trade ID: 5, Price: 100.11, Volume: 60 between ID:[1] and ID:[6]
82--INFO	Enqueued order: Price: 2147483647.00, Volume: 636, Type: BUY, Market Order: 1, Participant: 4, Stock:[ID: 0, Symbol: GOOG], Time: 82, OrderNumber: 8
84--INFO	Enqueued order: Price: 2147483647.00, Volume: 50, Type: BUY, Market Order: 1, Participant: 13, Stock:[ID: 0, Symbol: GOOG], Time: 84, OrderNumber: 9
85--INFO	Enqueued order: Price: 0.00, Volume: 239, Type: SELL, Market Order: 1, Participant: 12, Stock:[ID: 0, Symbol: GOOG], Time: 85, OrderNumber: 10
86--INFO	Last Price Set:100.11
86--INFO	Notified Traders of trade86---Trade ID: 6, Price: 100.11, Volume: 239 between ID:[1] and ID:[12]
90--INFO	Enqueued order: Price: 0.00, Volume: 615, Type: SELL, Market Order: 1, Participant: 9, Stock:[ID: 0, Symbol: GOOG], Time: 90, OrderNumber: 11
91--INFO	Last Price Set:100.11
91--INFO	Notified Traders of trade91---Trade ID: 7, Price: 100.11, Volume: 603 between ID:[1] and ID:[9]
91--INFO	Last Price Set:100.11
91--INFO	Notified Traders of trade91---Trade ID: 8, Price: 100.11, Volume: 12 between ID:[15] and ID:[9]
93--INFO	Enqueued order: Price: 0.00, Volume: 615, Type: SELL, Market Order: 1, Participant: 0, Stock:[ID: 0, Symbol: GOOG], Time: 93, OrderNumber: 12
94--INFO	Last Price Set:100.11
94--INFO	Notified Traders of trade94---Trade ID: 9, Price: 100.11, Volume: 615 between ID:[15] and ID:[0]
94--INFO	Enqueued order: Price: 2147483647.00, Volume: 377, Type: BUY, Market Order: 1, Participant: 8, Stock:[ID: 0, Symbol: GOOG], Time: 94, OrderNumber: 13
97--INFO	Enqueued order: Price: 0.00, Volume: 25, Type: SELL, Market Order: 1, Participant: 14, Stock:[ID: 0, Symbol: GOOG], Time: 97, OrderNumber: 14
98--INFO	Last Price Set:100.11
98--INFO	Notified Traders of trade98---Trade ID: 10, Price: 100.11, Volume: 25 between ID:[15] and ID:[14]
100--INFO	Enqueued order: Price: 0.00, Volume: 390, Type: SELL, Market Order: 1, Participant: 5, Stock:[ID: 0, Symbol: GOOG], Time: 100, OrderNumber: 15
101--INFO	Last Price Set:100.11
101--INFO	Notified Traders of trade101---Trade ID: 11, Price: 100.11, Volume: 12 between ID:[15] and ID:[5]
101--INFO	Last Price Set:100.11
101--INFO	Notified Traders of trade101---Trade ID: 12, Price: 100.11, Volume: 378 between ID:[4] and ID:[5]
102--INFO	Enqueued order: Price: 0.00, Volume: 587, Type: SELL, Market Order: 1, Participant: 3, Stock:[ID: 0, Symbol: GOOG], Time: 102, OrderNumber: 16
103--INFO	Last Price Set:100.11
103--INFO	Notified Traders of trade103---Trade ID: 13, Price: 100.11, Volume: 258 between ID:[4] and ID:[3]
103--INFO	Last Price Set:100.11
103--INFO	Notified Traders of trade103---Trade ID: 14, Price: 100.11, Volume: 50 between ID:[13] and ID:[3]
103--INFO	Last Price Set:100.11
103--INFO	Notified Traders of trade103---Trade ID: 15, Price: 100.11, Volume: 279 between ID:[8] and ID:[3]
107--INFO	Enqueued order: Price: 100.05, Volume: 432, Type: BUY, Market Order: 0, Participant: 7, Stock:[ID: 0, Symbol: GOOG], Time: 107, OrderNumber: 17
107--INFO	Enqueued order: Price: 0.00, Volume: 40, Type: SELL, Market Order: 1, Participant: 11, Stock:[ID: 0, Symbol: GOOG], Time: 107, OrderNumber: 18
109--INFO	Last Price Set:100.11
109--INFO	Notified Traders of trade109---Trade ID: 16, Price: 100.11, Volume: 40 between ID:[8] and ID:[11]
113--INFO	Enqueued order: Price: 2147483647.00, Volume: 209, Type: BUY, Market Order: 1, Participant: 10, Stock:[ID: 0, Symbol: GOOG], Time: 113, OrderNumber: 19
130--INFO	Enqueued order: Price: 0.00, Volume: 632, Type: SELL, Market Order: 1, Participant: 2, Stock:[ID: 0, Symbol: GOOG], Time: 130, OrderNumber: 20
131--INFO	Last Price Set:100.11
131--INFO	Notified Traders of trade131---Trade ID: 17, Price: 100.11, Volume: 58 between ID:[8] and ID:[2]
131--INFO	Last Price Set:100.11
131--INFO	Notified Traders of trade131---Trade ID: 18, Price: 100.11, Volume: 209 between ID:[10] and ID:[2]
131--INFO	Last Price Set:100.05
131--INFO	Notified Traders of trade131---Trade ID: 19, Price: 100.05, Volume: 365 between ID:[7] and ID:[2]
135--INFO	Enqueued order: Price: 2147483647.00, Volume: 80, Type: BUY, Market Order: 1, Participant: 9, Stock:[ID: 0, Symbol: GOOG], Time: 135, OrderNumber: 21
140--INFO	Enqueued order: Price: 2147483647.00, Volume: 971, Type: BUY, Market Order: 1, Participant: 1, Stock:[ID: 0, Symbol: GOOG], Time: 140, OrderNumber: 22
141--INFO	Enqueued order: Price: 0.00, Volume: 788, Type: SELL, Market Order: 1, Participant: 8, Stock:[ID: 0, Symbol: GOOG], Time: 141, OrderNumber: 23
142--INFO	Last Price Set:100.05
142--INFO	Notified Traders of trade142---Trade ID: 20, Price: 100.05, Volume: 80 between ID:[9] and ID:[8]
142--INFO	Last Price Set:100.05
142--INFO	Notified Traders of trade142---Trade ID: 21, Price: 100.05, Volume: 708 between ID:[1] and ID:[8]
150--INFO	Enqueued order: Price: 0.00, Volume: 643, Type: SELL, Market Order: 1, Participant: 5, Stock:[ID: 0, Symbol: GOOG], Time: 150, OrderNumber: 24
150--INFO	Enqueued order: Price: 0.00, Volume: 133, Type: SELL, Market Order: 1, Participant: 15, Stock:[ID: 0, Symbol: GOOG], Time: 150, OrderNumber: 25
151--INFO	Last Price Set:100.05
151--INFO	Notified Traders of trade151---Trade ID: 22, Price: 100.05, Volume: 263 between ID:[1] and ID:[5]
151--INFO	Last Price Set:100.05
151--INFO	Notified Traders of trade151---Trade ID: 23, Price: 100.05, Volume: 67 between ID:[7] and ID:[5]
153--INFO	Enqueued order: Price: 0.00, Volume: 318, Type: SELL, Market Order: 1, Participant: 3, Stock:[ID: 0, Symbol: GOOG], Time: 153, OrderNumber: 26
160--INFO	Enqueued order: Price: 2147483647.00, Volume: 699, Type: BUY, Market Order: 1, Participant: 6, Stock:[ID: 0, Symbol: GOOG], Time: 160, OrderNumber: 27
161--INFO	Last Price Set:100.05
161--INFO	Notified Traders of trade161---Trade ID: 24, Price: 100.05, Volume: 313 between ID:[6] and ID:[5]
161--INFO	Last Price Set:100.05
161--INFO	Notified Traders of trade161---Trade ID: 25, Price: 100.05, Volume: 133 between ID:[6] and ID:[15]
