OrderBookSim/OrderBookSim/Outputs/Output1361569052.txt
0,100,0,0,0
1,100,0,0,0
2,100,0,0,0
3,100,0,0,0
4,100,0,0,0
5,100,0,0,0
6,100,0,0,0
7,100,0,0,0
8,100,0,0,0
9,100,0,0,0
10,100,0,0,0
11,100,0,0,0
12,100,0,0,0
13,100,0,0,0
14,100,0,0,0
15,100,0,0,0
16,100,0,0,0
17,100,0,0,0
18,100,0,0,0
19,100,0,0,0
20,100,0,0,0
21,100,0,0,0
22,100,0,0,0
23,100,0,0,0
24,100,0,0,0
25,100,0,0,0
26,100,0,0,0
27,100,0,0,0
28,100,0,0,0
29,100,0,0,0
30,100,0,0,0
31,100,0,0,0
32,100,0,0,0
33,100,0,0,0
34,100,0,0,0
35,100,0,0,0
36,100,0,0,0
37,100,0,0,0
38,100,0,0,0
39,100,0,0,0
40,100,0,0,0
41,100,0,0,0
42,100,0,0,0
43,100,0,0,0
44,100,0,0,0
45,100,0,0,0
46,100,1,0,0
47,100,1,0,0
48,100.06,1,0,1
49,100.06,1,0,1
50,100.06,1,0,1
51,100.06,2,0,1
52,100.06,3,0,1
53,100.06,3,0,1
54,100.06,3,0,1
55,100.06,3,0,1
56,100.06,3,0,1
57,100.06,3,0,1
58,100.06,3,0,1
59,100.06,3,0,1
60,100.06,3,0,1
61,100.06,3,0,1
62,100.06,3,0,1
63,100.06,3,0,1
64,100.06,3,0,1
65,100.06,3,0,1
66,100.11,2,0,3
67,100.11,2,0,3
68,100.11,2,0,3
69,100.11,2,0,3
70,100.11,2,0,3
71,100.11,3,0,3
72,100.11,3,0,3
73,100.11,3,0,3
74,100.11,3,0,3
75,100.11,3,0,3
76,100.11,4,0,3
77,100.11,4,0,3
78,100.11,4,0,3
79,100.11,4,0,3
80,100.11,4,0,3
81,100.11,2,0,6
82,100.11,2,0,6
83,100.11,3,0,6
84,100.11,3,0,6
85,100.11,4,0,6
86,100.11,4,0,7
87,100.11,4,0,7
88,100.11,4,0,7
89,100.11,4,0,7
90,100.11,4,0,7
91,100.11,3,0,9
92,100.11,3,0,9
93,100.11,3,0,9
94,100.11,3,0,10
95,100.11,4,0,10
96,100.11,4,0,10
97,100.11,4,0,10
98,100.11,4,0,11
99,100.11,4,0,11
100,100.11,4,0,11
101,100.11,3,0,13
102,100.11,3,0,13
103,100.11,1,0,16
104,100.11,1,0,16
105,100.11,1,0,16
106,100.11,1,0,16
107,100.11,1,0,16
108,100.11,2,0,16
109,100.11,2,0,17
110,100.11,2,0,17
111,100.11,2,0,17
112,100.11,2,0,17
113,100.11,2,0,17
114,100.11,3,0,17
115,100.11,3,0,17
116,100.11,3,0,17
117,100.11,3,0,17
118,100.11,3,0,17
119,100.11,3,0,17
120,100.11,3,0,17
121,100.11,3,0,17
122,100.11,3,0,17
123,100.11,3,0,17
124,100.11,3,0,17
125,100.11,3,0,17
126,100.11,3,0,17
127,100.11,3,0,17
128,100.11,3,0,17
129,100.11,3,0,17
130,100.11,3,0,17
131,100.05,1,0,20
132,100.05,1,0,20
133,100.05,1,0,20
134,100.05,1,0,20
135,100.05,1,0,20
136,100.05,2,0,20
137,100.05,2,0,20
138,100.05,2,0,20
139,100.05,2,0,20
140,100.05,2,0,20
141,100.05,3,0,20
142,100.05,2,0,22
143,100.05,2,0,22
144,100.05,2,0,22
145,100.05,2,0,22
146,100.05,2,0,22
147,100.05,2,0,22
148,100.05,2,0,22
149,100.05,2,0,22
150,100.05,2,0,22
151,100.05,0,1,24
152,100.05,0,2,24
153,100.05,0,2,24
154,100.05,0,3,24
155,100.05,0,3,24
156,100.05,0,3,24
157,100.05,0,3,24
158,100.05,0,3,24
159,100.05,0,3,24
160,100.05,0,3,24
161,100.05,0,1,27
162,100.05,0,1,27
163,100.05,0,1,27
164,100.05,0,1,27
165,100.05,0,2,27
166,100.05,0,2,27
167,100.05,0,2,27
168,100.05,0,2,27
169,100.05,0,3,27
170,100.05,0,3,27
171,100.05,0,2,29
172,100.05,0,2,29
173,100.05,0,2,29
174,100.05,0,2,29
175,100.05,0,2,29
176,100.05,0,2,29
177,100.05,0,2,29
178,100.05,0,2,29
179,100.05,0,2,29
180,100.05,0,2,29
181,100.05,0,3,29
182,100.05,0,3,29
183,100.05,0,3,29
184,100.05,0,3,29
185,100.05,0,3,29
186,100.05,0,3,29
187,100.05,0,4,29
188,100.05,0,4,29
189,100.05,0,5,29
190,100.05,0,5,29
191,100.05,0,5,29
192,100.05,0,5,29
193,100.05,0,5,29
194,100.05,0,5,29
195,100.05,0,6,29
196,100.05,0,5,31
197,100.05,0,5,31
198,100.05,0,5,31
199,100.05,0,5,31
200,100.05,0,5,31
201,100.05,0,5,32
202,100.05,0,5,32
203,100.05,0,5,32
204,100.05,0,5,32
205,100.05,0,6,32
206,100.05,0,6,32
207,100.05,0,6,32
208,100.05,0,6,32
209,100.05,0,6,32
210,100.05,0,6,32
211,100.05,0,7,32
212,100.05,0,7,32
213,100.05,0,7,32
214,100.05,0,7,32
215,100.05,0,6,34
216,100.05,0,5,36
217,100.05,0,5,36
218,100.05,0,5,36
219,100.05,0,5,36
220,100.05,0,5,36
221,100.05,0,5,36
222,100.05,0,5,36
223,100.05,0,5,36
224,100.05,0,5,36
225,100.05,0,5,36
226,100.05,0,5,37
227,100.05,0,5,38
228,100.05,0,2,42
229,100.05,0,2,42
230,100.05,0,2,42
231,100.05,0,2,42
232,100.05,0,2,42
233,100.05,0,2,42
234,100.05,0,2,42
235,100.05,0,2,42
236,100.05,0,3,42
237,100.05,0,3,42
238,100.05,0,3,42
239,100.05,0,3,42
240,100.05,0,3,42
241,100.05,0,4,42
242,100.05,0,4,42
243,100.05,0,4,42
244,100.05,0,4,42
245,100.05,0,4,42
246,100.05,0,4,42
247,100.05,0,5,42
248,100.05,0,5,42
249,100.05,0,5,42
250,100.05,0,5,42
251,100.05,0,5,43
252,100.05,0,5,43
253,100.05,0,6,43
254,100.05,0,6,43
255,100.05,0,6,43
256,100.05,0,7,43
257,100.05,0,8,43
258,100.05,0,8,43
259,100.05,0,8,43
260,100.05,0,8,43
261,100.05,0,7,45
262,100.05,0,7,45
263,100.05,0,7,45
264,100.05,0,7,45
265,100.05,0,7,45
266,100.05,0,7,45
267,100.05,0,7,45
268,100.05,0,7,45
269,100.05,0,7,45
270,100.05,0,7,45
271,100.05,0,7,46
272,100.05,0,7,46
273,100.05,0,7,46
274,100.05,0,7,46
275,100.05,0,7,46
276,100.05,0,7,46
277,100.05,0,7,46
278,100.05,0,7,46
279,100.05,0,7,46
280,100.05,0,8,46
281,100.05,0,9,46
282,100.05,0,9,46
283,100.05,0,10,46
284,100.05,0,10,46
285,100.05,0,10,46
286,100.05,0,10,46
287,100.05,0,10,46
288,100.05,0,10,46
289,100.05,0,10,46
290,100.05,0,10,46
291,100.05,0,10,46
292,100.05,0,11,46
293,100.05,0,11,46
294,100.05,0,11,46
295,100.05,0,11,46
296,100.05,0,11,46
297,100.05,0,11,46
298,100.05,0,11,46
299,100.05,0,11,46
300,100.05,0,11,46
301,100.05,0,11,47
302,100.05,0,7,52
303,100.05,0,7,52
304,100.05,0,7,52
305,100.05,0,7,52
306,100.05,0,7,52
307,100.05,0,7,53
308,100.05,0,7,53
309,100.05,0,7,53
310,100.05,0,7,53
311,100.05,0,7,53
312,100.05,0,7,53
313,100.05,0,7,53
314,100.05,0,7,53
315,100.05,0,7,53
316,100.05,0,6,55
317,100.05,0,6,55
318,100.05,0,6,55
319,100.05,0,6,55
320,100.05,0,6,55
321,100.07,0,2,60
322,100.07,1,2,60
323,100.07,1,3,60
324,100.07,1,3,60
325,100.07,1,3,60
326,100.01,1,3,61
327,100.01,1,3,61
328,100.01,1,3,61
329,100.09,2,1,63
330,100.01,0,2,65
331,100.01,0,2,65
332,100.01,0,2,65
333,100.01,0,2,65
334,100.01,0,2,65
335,100.01,0,2,65
336,100.01,0,2,65
337,100.09,0,1,67
338,100.09,0,1,67
339,100.09,0,1,67
340,100.09,1,0,68
341,100.09,2,0,68
342,100.09,2,0,68
343,100.09,2,0,68
344,100.09,2,0,68
345,100.09,2,0,68
346,100.09,2,0,68
347,100.09,2,0,68
348,100.09,2,0,68
349,100.09,2,0,68
350,100.09,2,0,68
351,100.09,3,0,68
352,100.09,4,0,68
353,100.09,4,0,68
354,100.09,4,0,68
355,100.09,4,0,68
356,100.09,4,0,68
357,100.09,4,0,68
358,100.09,5,0,68
359,100.09,5,0,68
360,100.09,5,0,68
361,100.09,6,0,68
362,100.09,6,0,68
363,100.09,6,0,68
364,100.09,6,0,68
365,100.09,6,0,68
366,100.09,6,0,68
367,100.09,6,0,68
368,100.09,6,0,68
369,100.09,6,0,68
370,100.09,6,0,68
371,100.09,6,0,68
372,100.09,6,0,68
373,100.09,5,0,70
374,100.09,5,0,70
375,100.09,5,0,70
376,100.09,6,0,70
377,100.14,6,0,71
378,100.14,6,0,71
379,100.14,6,0,71
380,100.14,6,0,71
381,100.14,6,0,71
382,100.14,6,0,71
383,100.14,6,0,71
384,100.14,6,0,71
385,100.14,6,0,71
386,100.14,6,0,71
387,100.14,6,0,71
388,100.14,6,0,71
389,100.14,5,0,73
390,100.14,5,0,73
391,100.14,6,0,73
392,100.14,6,0,73
393,100.14,6,0,73
394,100.14,6,0,73
395,100.14,6,0,73
396,100.14,6,0,73
397,100.14,6,0,73
398,100.14,6,0,73
399,100.14,6,0,73
400,100.14,6,0,73
401,100.14,7,0,73
402,100.14,8,0,73
403,100.14,8,0,73
404,100.14,8,0,73
405,100.14,8,0,73
406,100.14,7,0,75
407,100.14,7,0,75
408,100.14,7,0,75
409,100.14,8,0,75
410,100.14,8,0,75
411,100.14,8,0,76
412,100.14,8,0,76
413,100.14,8,0,76
414,100.14,8,0,76
415,100.14,8,0,76
416,100.14,8,0,76
417,100.14,8,0,76
418,100.14,8,0,76
419,100.14,8,0,76
420,100.14,8,0,76
421,100.14,7,0,78
422,100.14,8,0,78
423,100.14,8,0,78
424,100.14,8,0,79
425,100.14,8,0,79
426,100.14,9,0,79
427,100.14,9,0,79
428,100.14,9,0,79
429,100.14,10,0,79
430,100.14,9,0,81
431,100.14,9,0,81
432,100.14,9,0,81
433,100.14,9,0,81
434,100.14,9,0,81
435,100.14,9,0,81
436,100.14,9,0,81
437,100.14,9,0,81
438,100.14,9,0,81
439,100.14,9,0,81
440,100.14,9,0,81
441,100.14,9,0,81
442,100.14,9,0,81
443,100.14,9,0,81
444,100.14,9,0,81
445,100.14,9,0,81
446,100.14,9,0,81
447,100.14,9,0,81
448,100.14,9,0,81
449,100.14,9,0,81
450,100.14,9,0,81
451,100.14,8,0,83
452,100.14,9,0,83
453,100.14,10,0,83
454,100.14,9,0,85
455,100.14,9,0,85
456,100.14,9,0,86
457,100.14,9,0,86
458,100.14,9,0,86
459,100.14,9,0,86
460,100.14,8,0,88
461,100.14,8,0,88
462,100.14,8,0,88
